Workbook

Sheet alldataentered11-2MG
A1: Plot # | B1: Number of expected plants | C1: # survived 8-4 | D1: # survived 8-14 | E1: # survived 9-1 | F1: # survived 9-11 | G1: # survived 9-21 | H1: # survived 10-9 | I1: # survived 10-23 | J1: average height 8-4 | K1: average height 8-14 | L1: average height 9-1 | M1: average height 9-11 | N1: average height 9-21 | O1: average height 10-9 | P1: average height 10-23 | Q1: average # of stems 8-4 | R1: average # of stems 8-14 | S1: average # of stems 9-1 | T1: average # of stems 9-11 | U1: average # of stems 9-21 | V1: average # of stems 10-9 | W1: average # of stems 10-23
A2: ACMI plot 1 | B2: 50 | C2: 37 | D2: 37 | E2: 39 | H2: 32 | I2: ='10-23-25 AB'!G38 -> 33 | J2: ='8-4-25-MG'!E69 -> 9.4666667 | K2: 9.8 | L2: 8.2 | O2: 8.3 | P2: ='10-23-25 AB'!H38 -> 8.4242424 | Q2: ='8-4-25-MG'!F69 -> 2.7777778 | V2: 1.2 | W2: ='10-23-25 AB'!I38 -> 1.6060606
A3: ACMI plot 2 | B3: 60 | C3: 34 | D3: 32 | E3: 34 | H3: 32 | I3: ='10-23-25 AB'!G75 -> 37 | J3: ='8-4-25-MG'!E160 -> 9.6029412 | K3: 10.2 | L3: 3 | O3: 9 | P3: ='10-23-25 AB'!H75 -> 8.6756757 | Q3: ='8-4-25-MG'!F160 -> 2.6176471 | V3: 1.3 | W3: ='10-23-25 AB'!I75 -> 2.1891892
A4: ACMI plot 3
A5: ACMI plot 4
A6: ACMI plot 5
A7: ACMI plot 6 | B7: 40 | D7: 40 | E7: 9 | I7: ='10-23-25 AB'!G84 -> 9 | L7: 2.8 | P7: ='10-23-25 AB'!H84 -> 4.7777778 | W7: ='10-23-25 AB'!I84 -> 1
A8: ACMI plot 7 | B8: 25 | D8: 25 | I8: ='10-23-25 AB'!G107 -> 23 | K8: 13.7 | L8: 11 | P8: ='10-23-25 AB'!H107 -> 8.5652174 | S8: 1.4 | W8: ='10-23-25 AB'!I107 -> 1.4782609
A9: ACMI plot 8 | B9: 25 | D9: 25 | E9: 14 | I9: ='10-23-25 AB'!G116 -> 9 | K9: 17.7 | O9: 12.5 | P9: ='10-23-25 AB'!H116 -> 7.2222222 | W9: ='10-23-25 AB'!I116 -> 1
A10: ACMI plot 9 | B10: 22 | F10: 22 | H10: 17 | I10: ='10-23-25 AB'!G137 -> 21 | M10: ='9-11-25-KT'!G326 -> 4.1428571 | O10: 3.8 | P10: ='10-23-25 AB'!H137 -> 3.3333333 | W10: ='10-23-25 AB'!I137 -> 1.047619
A11: ACMI plot 10 | B11: 24 | F11: 24 | I11: ='10-23-25 AB'!G164 -> 27 | M11: ='9-11-25-KT'!G305 -> 3.3913043 | O11: 3.4 | P11: ='10-23-25 AB'!H164 -> 3.4444444 | W11: ='10-23-25 AB'!I164 -> 1.037037
A12: ACMI plot 11 | B12: 20 | F12: 20 | I12: ='10-23-25 AB'!G182 -> 18 | M12: ='9-11-25-KT'!G282 -> 7.8947368 | O12: 5.6 | P12: ='10-23-25 AB'!H182 -> 4.9444444 | S12: 1 | W12: ='10-23-25 AB'!I182 -> 1
A13: ACMI plot 12 | B13: 24 | F13: 24 | H13: 24 | I13: ='10-23-25 AB'!G202 -> 20 | M13: ='9-11-25-KT'!G263 -> 5.55 | O13: 5.6 | P13: ='10-23-25 AB'!H202 -> 6 | W13: ='10-23-25 AB'!I202 -> 1
A14: ARLU plot 1 | B14: 15 | C14: ='8-4-25-MG'!G83 -> 12 | E14: ='9-1-25-LM'!B91 -> 14 | H14: 15 | I14: ='10-23-25 AB'!G222 -> 14 | J14: ='8-4-25-MG'!E83 -> 7.6923077 | K14: 7.4 | L14: =average('9-1-25-LM'!D78:D91) -> 5.5714286 | O14: 4.8 | P14: ='10-23-25 AB'!H222 -> 5.1428571 | Q14: =average('9-1-25-LM'!E78:E91) -> 2.5 | V14: 1.9 | W14: ='10-23-25 AB'!I222 -> 1
A15: ARLU plot 2 | B15: 15 | C15: ='8-4-25-MG'!G175 -> 7 | D15: 7 | E15: ='9-1-25-LM'!B97 -> 4 | H15: 4 | I15: ='10-23-25 AB'!G226 -> 4 | J15: ='8-4-25-MG'!E175 -> 7.2142857 | L15: =average('9-1-25-LM'!D92:D97) -> 4.5 | O15: 5.5 | P15: ='10-23-25 AB'!H226 -> 4.25 | Q15: ='8-4-25-MG'!F175 -> 2 | S15: =average('9-1-25-LM'!E92:E97) -> 1.75 | V15: 2 | W15: ='10-23-25 AB'!I226 -> 1
A16: ARLU plot 3 | B16: 0
A17: ARLU plot 4 | B17: 0
A18: ARLU plot 5 | B18: 0
A19: ARLU plot 6 | B19: 0
A20: ARLU plot 7 | B20: 13 | D20: 13 | E20: ='9-1-25-LM'!B110 -> 10 | H20: 10 | I20: ='10-23-25 AB'!G236 -> 10 | K20: 15.7 | L20: =average('9-1-25-LM'!D98:D110) -> 8.9 | O20: 8.1 | P20: ='10-23-25 AB'!H236 -> 8.2 | S20: =average('9-1-25-LM'!E98:E110) -> 3 | V20: 1.3 | W20: ='10-23-25 AB'!I236 -> 1
A21: ARLU plot 8 | B21: 25 | D21: 24 | E21: ='9-1-25-LM'!B135 -> 16 | H21: 17 | I21: ='10-23-25 AB'!G258 -> 22 | K21: 12.6 | L21: =average('9-1-25-LM'!D111:D134) -> 7 | O21: 5.6 | P21: ='10-23-25 AB'!H258 -> 6.2727273 | S21: =average('9-1-25-LM'!E111:E135) -> 2.5625 | V21: 1.1 | W21: ='10-23-25 AB'!I258 -> 1
A22: ARLU plot 9 | B22: 24 | F22: 24 | H22: 20 | I22: ='10-23-25 AB'!G269 -> 11 | M22: ='9-11-25-KT'!G241 -> 3.4 | O22: 2.7 | V22: 1.1
A23: ARLU plot 10 | B23: 24 | F23: 24 | H23: 10 | I23: ='10-23-25 AB'!G281 -> 12 | M23: ='9-11-25-KT'!G216 -> 2.3333333 | O23: 3.7 | V23: 1
A24: ARLU plot 11 | B24: 23 | F24: 23 | I24: ='10-23-25 AB'!G294 -> 13 | M24: =average('9-11-25-KT'!G166) -> 3.5454545
A25: ARLU plot 12 | B25: 24 | F25: 24 | I25: ='10-23-25 AB'!G313 -> 19 | M25: ='9-11-25-KT'!G192 -> 2.8076923
A26: HEVI plot 1 | B26: 15 | C26: ='9-1-25-LM'!B18 -> 13 | D26: 12 | E26: 13 | H26: ='10-9-25-EB'!C18 -> 13 | I26: ='10-23-25 AB'!G330 -> 11 | J26: =average('9-1-25-LM'!D6:D18) -> 10.615385 | K26: 10.4 | L26: =average('9-1-25-LM'!D6:D18) -> 10.615385 | O26: ='10-9-25-EB'!G18 -> 11.115385 | P26: ='10-23-25 AB'!H330 -> 11.090909 | Q26: ='8-4-25-MG'!F95 -> 1.5 | S26: =average('9-1-25-LM'!E19:E22) -> 1.75 | V26: ='10-9-25-EB'!H18 -> 1
A27: HEVI plot 2 | B27: 15 | C27: ='8-4-25-MG'!G187 -> 10 | D27: 11 | E27: ='9-1-25-LM'!B22 -> 4 | H27: ='10-9-25-EB'!C23 -> 5 | I27: ='10-23-25 AB'!G334 -> 4 | J27: ='8-4-25-MG'!E187 -> 5.75 | K27: 7.3 | L27: =average('9-1-25-LM'!D19:D22) -> 6.5 | O27: ='10-9-25-EB'!G27 -> 6.1 | P27: ='10-23-25 AB'!H334 -> 7.25 | Q27: ='8-4-25-MG'!F187 -> 1 | V27: ='10-9-25-EB'!H27 -> 1 | W27: ='10-23-25 AB'!I334 -> 1
A28: HEVI plot 3 | B28: 21 | C28: ='8-4-25-MG'!G225 -> 11 | D28: 10 | E28: ='9-1-25-LM'!B37 -> 15 | H28: ='10-9-25-EB'!C35 -> 8 | I28: ='10-23-25 AB'!G346 -> 12 | J28: ='8-4-25-MG'!E225 -> 1.9090909 | K28: 3.4 | L28: =average('9-1-25-LM'!D23:D37) -> 3.8 | O28: ='10-9-25-EB'!G35 -> 3.3125 | P28: ='10-23-25 AB'!H346 -> 3.3333333 | Q28: =average('9-1-25-LM'!E23:E37) -> 1.2 | V28: ='10-9-25-EB'!H35 -> 1 | W28: ='10-23-25 AB'!I346 -> 1
A29: HEVI plot 4 | B29: 15 | C29: ='8-4-25-MG'!G297 -> 11 | D29: 11 | E29: 15 | H29: ='10-9-25-EB'!C47 -> 12 | I29: ='10-23-25 AB'!G360 -> 14 | J29: ='8-4-25-MG'!E297 -> 2.4545455 | K29: 3.5 | L29: =average('9-1-25-LM'!D38:D53) -> 4.75 | O29: ='10-9-25-EB'!G47 -> 3.9583333 | P29: ='10-23-25 AB'!H360 -> 3.0714286 | S29: =average('9-1-25-LM'!E38:E53) -> 1.0625 | V29: ='10-9-25-EB'!H47 -> 1 | W29: ='10-23-25 AB'!I360 -> 1
A30: HEVI plot 5 | B30: 0
A31: HEVI plot 6 | B31: 0
A32: HEVI plot 7 | B32: 9 | D32: 9 | E32: ='9-1-25-LM'!B62 -> 7 | F32: 7 | H32: ='10-9-25-EB'!C55 -> 8 | I32: ='10-23-25 AB'!G367 -> 7 | J32: =average('9-1-25-LM'!D54:D62) -> 20.142857 | K32: 20.9 | L32: =average('9-1-25-LM'!D54:D62) -> 20.142857 | O32: ='10-9-25-EB'!G55 -> 18.625 | P32: ='10-23-25 AB'!H367 -> 19.285714 | Q32: =average('9-1-25-LM'!E54:E62) -> 1.1428571 | V32: ='10-9-25-EB'!H55 -> 1 | W32: ='10-23-25 AB'!I367 -> 1
A33: HEVI plot 8 | B33: 10 | D33: 10 | H33: 0 | I33: ='10-23-25 AB'!G368 -> 1 | K33: 29.8 | P33: ='10-23-25 AB'!H368 -> 13 | W33: ='10-23-25 AB'!I380 -> 1
A34: HEVI plot 9 | B34: 5 | F34: 5 | H34: 5 | I34: ='10-23-25 AB'!G373 -> 5 | M34: 9.8 | O34: 2.8
A35: HEVI plot 10 | B35: 0
A36: HEVI plot 11 | B36: 7 | F36: 7 | H36: 7 | I36: ='10-23-25 AB'!G380 -> 7 | M36: 2.9 | O36: 2.6 | P36: ='10-23-25 AB'!H380 -> 2.1428571 | W36: ='10-23-25 AB'!I380 -> 1
A37: HEVI plot 12 | B37: 0 | P37: =#REF! -> #REF! | W37: =#REF! -> #REF!
A38: BOGR plot 1 | B38: 7 | C38: ='8-4-25-MG'!G114 -> 4 | D38: 5 | E38: 4 | F38: ='9-11-25-KT'!C9 -> 4 | H38: 4 | I38: ='10-23-25 AB'!G390 -> 4 | J38: ='8-4-25-MG'!E114 -> 22.5 | L38: 16 | M38: =average('9-11-25-KT'!D6:D9) -> 12.5 | O38: 10.8 | P38: ='10-23-25 AB'!H390 -> 16
A39: BOGR plot 2 | B39: 7 | C39: ='8-4-25-MG'!G205 -> 5 | D39: 3 | E39: 6 | F39: ='9-11-25-KT'!C13 -> 4 | H39: 4 | I39: ='10-23-25 AB'!G395 -> 5 | J39: ='8-4-25-MG'!E205 -> 16.7 | L39: 14.7 | M39: =average('9-11-25-KT'!D10:D13) -> 14.25 | O39: 14.3 | P39: ='10-23-25 AB'!H395 -> 19.6
A40: BOGR plot 3 | B40: 32 | C40: ='8-4-25-MG'!G276 -> 27 | D40: 24 | E40: 24 | F40: ='9-11-25-KT'!C39 -> 26 | H40: 26 | I40: ='10-23-25 AB'!G404 -> 9 | J40: ='8-4-25-MG'!E276 -> 6.037037 | L40: 7.5 | M40: =average('9-11-25-KT'!D14:D39) -> 6.3846154 | O40: 6.4
...

Sheet all spp germ MCPeat
A1: Species | B1: Mineral - compost soil | C1: Peat
A2: ACMI | B2: =65/98 -> 0.66326531 | C2: =60/98 -> 0.6122449
A3: ARLU | B3: =89/98 -> 0.90816327 | C3: =91/98 -> 0.92857143
A4: HEVI | B4: =86/98 -> 0.87755102 | C4: =95/98 -> 0.96938776
A5: SYER | B5: =88/98 -> 0.89795918 | C5: =88/98 -> 0.89795918
A6: BOGR | B6: =71/98 -> 0.7244898 | C6: =70/98 -> 0.71428571
A7: HECO | B7: =67/98 -> 0.68367347 | C7: =61/98 -> 0.62244898
A8: NAVI | B8: =77/98 -> 0.78571429 | C8: =80/98 -> 0.81632653
A9: PASM | B9: =83/98 -> 0.84693878 | C9: =93/98 -> 0.94897959

Sheet total planted
A1: date planted # of individuals planted | B1: plot name | C1: ACMI | D1: ARLU | E1: HEVI | F1: SYER | G1: BOGR | H1: HECO | I1: NAVI | J1: PASM
A2: 45848 | B2: 1-F-S3 | C2: 50 | D2: 15 | E2: 15 | F2: 15 | G2: 7 | I2: 5 | J2: 10
A3: 45848 | B3: 2-NF-S3 | C3: 60 | D3: 15 | E3: 15 | F3: 10 | G3: 7 | I3: 5 | J3: 10
A4: 45848 | B4: 3-F-peat | E4: 21 | F4: 48 | G4: 32 | H4: 10 | I4: 9
A5: 45848 | B5: 4-NF-peat | E5: 15 | F5: 49 | G5: 30 | I5: 9 | L5: total plants per planting date
A6: 45848 | B6: 5-NF-MC 7-10BOGR+8-14 | F6: 9 | G6: 32 | H6: 3 | I6: 6 | L6: total plants 7-10-25
A7: 45848 | B7: 6-F-peat 7-10BOGR+8-14 | C7: 40 | F7: 23 | G7: 32 | H7: 5 | I7: 6 | J7: 9 | K7: total plants per soil treatment | L7: =sum(C2:J5)+sum(G6:G7) -> 526
A8: 45883 | B8: 7-F-S3 8-14 | C8: 25 | D8: 13 | E8: 9 | F8: 15 | G8: 6 | I8: 6 | J8: 9 | K8: S3
A9: 45883 | B9: 8-NF-S3 8-14 | C9: 25 | D9: 25 | E9: 10 | F9: 15 | G9: 10 | I9: 6 | J9: 6 | K9: =sum(C2:J3)+sum(C8:J9) -> 419 | L9: total plants 8-14-25
A10: 45911 | B10: 9-F peat 9-11 | C10: 22 | D10: 24 | E10: 5 | G10: 25 | I10: 8 | J10: 1 | K10: peat | L10: =sum(C6:F9)+sum(G8:G9)+sum(H6:J9) -> 281
A11: 45911 | B11: 10-NF peat 9-11 | C11: 24 | D11: 24 | G11: 24 | I11: 3 | J11: 9 | K11: =sum(C4:J5)+sum(C10:J11)+sum(C7:J7) -> 507
A12: 45911 | B12: 11-F MC 9-11 | C12: 20 | D12: 23 | E12: 7 | G12: 25 | J12: 9 | K12: MC | L12: total plants 9-11-25
A13: 45911 | B13: 12NF MC 9-11 | C13: 24 | D13: 24 | G13: 24 | I13: 2 | J13: 13 | K13: =sum(C6:J6)+sum(C12:J13) -> 221 | L13: =sum(C10:J13) -> 340
C14: ACMI | D14: ARLU | E14: HEVI | F14: SYER | G14: BOGR | H14: HECO | I14: NAVI | J14: PASM
C15: =sum(C2:C13) -> 290 | D15: =sum(D2:D13) -> 163 | E15: =sum(E2:E13) -> 97 | F15: =sum(F2:F13) -> 184 | G15: =sum(G2:G13) -> 254 | H15: =sum(H2:H13) -> 18 | I15: =sum(I2:I13) -> 65 | J15: =sum(J2:J13) -> 76 | K15: =sum(K9:K13) -> 1147
E16: forbs | F16: =sum(C15:F15) -> 734 | I16: grasses | J16: =sum(G15:J15) -> 413 | K16: =sum(C15:J15) -> 1147
K17: =sum(J16+F16) -> 1147 | L17: =sum(L7+L10+L13) -> 1147 | M17: total plants planted
F19: 0

Sheet worksheet 
A1: JCOS-CoNPS Plant Growth Study 2025
A2: write species name here:
A3: date:
A5: Plot # | B5: Number of expected plants 1. write this in from 7-10-25 tab | C5: Count individuals 1. write species code here. One individual per row. 2. stick with one species until it is complete. | D5: Plant height (cm) 1. pull tallest stem straight up 2. measure it's length | E5: Number of stems 1. count how many stems/individual *forbs only | F5: Code 1. Add B, H, or G if you see insect damage (B), herbivory (H), growth (G), flower (F)
A60: Plot # | B60: Number of expected plants 1. write this in from 7-10-25 tab | C60: Count individuals 1. write species code here. One individual per row. 2. stick with one species until it is complete. | D60: Plant height (cm) 1. pull tallest stem straight up 2. measure it's length | E60: Number of stems 1. count how many stems/individual *forbs only | F60: Code 1. Add B, H, or G if you see insect damage (B), herbivory (H), or growth (G)
C106: Species Code Key | D106: Plot Code Key | E106: Site Acronyms | F106: Measurement Codes
C107: ACMI - Achillea millifolium yarrow | D107: 1-F-S3 7-10 | E107: F = fertilized | F107: B = insect damage (bugs)
C108: SYER - Symphyotrichum ericoides white aster | D108: 2-NF-S3 7-10 | E108: NF = not fertilized | F108: H = evidence of herbivory
C109: ARLU - Artemisia ludoviciana white mountain sage/ silver wormwood | D109: 3-F-peat 7-10 | E109: peat = peat soil | F109: G = the plant has new leaves and stems emerging (growth)
C110: HEVI - Heterotheca villosa hairy goldenaster | D110: 4-NF-peat 7-10 | E110: MC = mineral/ compost soil
C111: PASM - Pascopyrum smithii western wheatgrass | D111: 5-NF-MC 7-10BOGR and 8-14 | E111: S3 = soil type 3 native soil/compost
C112: BOGR - Bouteloua gracilis blue grama | D112: 6-F-peat 7-10BOGR and 8-14
C113: NAVI - Nasella viridula green needle | D113: 7-F-S3 8-14
C114: HECO - Hesperostipa comata needle and thread grass | D114: 8-NF-S3 8-14

Sheet 8-4-25-MG
A1: Survival rate | B1: ACMI | C1: ARLU | D1: HEVI | E1: SYER | F1: BOGR | G1: HECO | H1: NAVI | I1: PASM | J1: conclusion from rows 1-2: F did better than NF in S3. SYER is the exception but lots of these plants were apparently dug up by fauna. We also noticed that these plants were not planted as well, which might have contributed to the results.
A2: 1-F-S3 | B2: =(46-9)/50 -> 0.74 | C2: =(14-1)/15 -> 0.86666667 | D2: =(12-0)/15 -> 0.8 | E2: =(13-9)/15 -> 0.26666667 | F2: =(6-1)/7 -> 0.71428571 | H2: =(2-0)/5 -> 0.4 | I2: =(9-4)/10 -> 0.5
A3: 2-NF-S3 | B3: =(37-3)/60 -> 0.56666667 | C3: =(15-8)/15 -> 0.46666667 | D3: =(13-2)/15 -> 0.73333333 | E3: =(10-5)/10 -> 0.5 | F3: =(5-2)/7 -> 0.42857143 | H3: =(5-4)/5 -> 0.2 | I3: =(3-2)/10 -> 0.1
A4: Survival rate | B4: ACMI | C4: ARLU | D4: HEVI | E4: SYER | F4: BOGR | G4: HECO | H4: NAVI | I4: PASM | J4: conclusion from rows 3-4: NF plants did better than F in peat. This is an interesting result because we know the peat is more nutrient-rich already.
A5: 3-F-peat | D5: =(11-1)/21 -> 0.47619048 | E5: =(24-11)/48 -> 0.27083333 | F5: =(27-0)/32 -> 0.84375 | G5: =(7-3)/10 -> 0.4 | H5: =(3-2)/9 -> 0.11111111
A6: 4-NF-peat | D6: =(11-0)/15 -> 0.73333333 | E6: =(26-0)/49 -> 0.53061224 | F6: =(29-0)/30 -> 0.96666667 | H6: =(9-7)/9 -> 0.22222222
A7: Survival rate | B7: ACMI | C7: ARLU | D7: HEVI | E7: SYER | F7: BOGR | G7: HECO | H7: NAVI | I7: PASM | J7: conclusion from rows 5-6: BOGR in MC did better than BOGR in peat, even though MC was F and peat was NF. Peat F plants did not do as well as peat NF in plots 3-4. Perhaps the F contributed to this BOGR result. Of note, this sample is large and the survival rates are dramatically different in MC soil v. peat. Not sure at this point if that is attributed to soil type or fertilization. It is worth noting that these two treatments survived while their compliment treatments did not (MC F and peat NF) when they were being hardened off coming out of the greenhouse.
A8: 5-NF-MC | F8: =(31-0)/32 -> 0.96875
A9: 6-F-peat | F9: =(28-7)/32 -> 0.65625
A11: Survival rate | B11: BOGR
A12: 5-NF-MC | B12: =(30-0)/32 -> 0.9375
A13: 6-F-peat | B13: =(27-7)/32 -> 0.625
A15: count individuals | B15: plant height (cm) | C15: # of stems | D15: code (H, B, G) | E15: Average plant height | F15: average # of stems
A16: plot 1 ACMI | B16: 6.5 | C16: 2
A17: plot 1 ACMI | B17: 12 | C17: 2
A18: plot 1 ACMI | B18: 11.5 | C18: 2
A19: plot 1 ACMI | B19: x
A20: plot 1 ACMI | B20: x
A21: plot 1 ACMI | B21: x
A22: plot 1 ACMI | B22: x
A23: plot 1 ACMI | B23: x
A24: plot 1 ACMI | B24: x
A25: plot 1 ACMI | B25: x
A26: plot 1 ACMI | B26: 8.5 | C26: 3
A27: plot 1 ACMI | B27: 12 | C27: 4
A28: plot 1 ACMI | B28: x
A29: plot 1 ACMI | B29: x
A30: plot 1 ACMI | B30: 10 | C30: 2
A31: plot 1 ACMI | B31: 9 | C31: 4
A32: plot 1 ACMI | B32: 10 | C32: 3
A33: plot 1 ACMI | B33: 8 | C33: 2 | D33: H
A34: plot 1 ACMI | B34: 8 | C34: 3
A35: plot 1 ACMI | B35: 9.5 | C35: 2
A36: plot 1 ACMI | B36: 8 | C36: 2 | D36: H
A37: plot 1 ACMI | B37: 8 | C37: 2
A38: plot 1 ACMI | B38: 8 | C38: 2
A39: plot 1 ACMI | B39: 12 | C39: 4 | D39: G
A40: plot 1 ACMI | B40: 11 | C40: 3
A41: plot 1 ACMI | B41: 6 | C41: 3
A42: plot 1 ACMI | B42: 7 | C42: 3 | D42: G
...

Sheet 8-14-25-MG
A1: Survival rate | B1: ACMI | C1: ARLU | D1: HEVI | E1: SYER | F1: BOGR | G1: HECO | H1: NAVI | I1: PASM
A2: 1-F-S3 7-10 | B2: =37/50 -> 0.74 | C2: =13/15 -> 0.86666667 | D2: =12/12 -> 1 | E2: =4/15 -> 0.26666667 | F2: =5/7 -> 0.71428571 | G2: - | H2: =2/5 -> 0.4 | I2: =5/10 -> 0.5
A3: 2-NF-S3 7-10 | B3: =34/50 -> 0.68 | C3: =7/15 -> 0.46666667 | D3: =7/11 -> 0.63636364 | E3: =5/10 -> 0.5 | F3: =3/7 -> 0.42857143 | G3: - | H3: =1/5 -> 0.2 | I3: =1/10 -> 0.1
A4: Survival rate | B4: ACMI | C4: ARLU | D4: HEVI | E4: SYER | F4: BOGR | G4: HECO | H4: NAVI | I4: PASM
A5: 3-F-peat 7-10 | D5: =8/10 -> 0.8 | E5: =13/48 -> 0.27083333 | F5: =27/32 -> 0.84375 | G5: =4/10 -> 0.4 | H5: =1/9 -> 0.11111111 | I5: -
A6: 4-NF-peat 7-10 | D6: =11/15 -> 0.73333333 | E6: =26/49 -> 0.53061224 | F6: =29/30 -> 0.96666667 | G6: - | H6: =2/9 -> 0.22222222 | I6: -
A7: Survival rate | B7: ACMI | C7: ARLU | D7: HEVI | E7: SYER | F7: BOGR | G7: HECO | H7: NAVI | I7: PASM
A8: 5-NF-MC 7-10BOGR+8-14 | E8: /9 | F8: =31/32 -> 0.96875 | G8: =3/3 -> 1 | H8: =6/6 -> 1 | I8: -
A9: 6-F-peat 7-10BOGR+8-14 | B9: =40/40 -> 1 | E9: /23 | F9: =21/32 -> 0.65625 | G9: =5/5 -> 1 | H9: =4/4 -> 1 | I9: =9/9 -> 1
A10: 7-F-S3 8-14 | B10: =25/25 -> 1 | C10: =13/13 -> 1 | D10: =9/9 -> 1 | E10: =15/15 -> 1 | F10: =6/6 -> 1 | H10: =6/6 -> 1 | I10: =9/9 -> 1
A11: 8-NF-S3 8-14 | B11: =25/25 -> 1 | C11: =25/25 -> 1 | D11: =10/10 -> 1 | E11: =15/15 -> 1 | F11: =10/10 -> 1 | H11: =6/6 -> 1 | I11: =6/6 -> 1
A12: 9-F peat 9-11 | E12: =9/9 -> 1
A13: 10-NF peat 9-11 | B13: /24 | C13: /24 | D13: /2 | F13: /24 | H13: /3 | I13: /9
A14: 11-F MC 9-11
A15: 12NF MC 9-11
A18: 8-14-25 data added
A20: JCOS-CoNPS Plant Growth Study 2025
A21: write species name here: HEVI
A22: date: 8-14-25
A24: Plot # | B24: Number of expected plants 1. write this in from 7-10-25 tab | C24: Count individuals 1. write species code here. One individual per row. 2. stick with one species until it is complete. | D24: Plant height (cm) 1. pull tallest stem straight up 2. measure it's length | E24: Number of stems 1. count how many stems/individual *forbs only | F24: Code 1. Add B, H, or G if you see insect damage (B), herbivory (H), growth (G), flower (F)
A25: 1 | C25: HEVI | D25: 6 | E25: 1
D26: 4 | E26: 1
D27: 10.5 | E27: 1
D28: 5.5 | E28: 1
D29: 11.5 | E29: 1
D30: 23 | E30: 1
D31: 8 | E31: 2
D32: 9.5 | E32: 1
D33: 12 | E33: 1
D34: 6 | E34: 1
D35: 10.5 | E35: 1
D36: 18 | E36: 1
A37: 2 | C37: HEVI | D37: 3.5 | E37: 1
D38: 7 | E38: 1
D39: 8 | E39: 1
D40: 6 | E40: 1
D41: 9 | E41: 1
D42: 8.5 | E42: 1
D43: 9 | E43: 1
A44: 3 | C44: HEVI | D44: 4 | E44: 1
...

Sheet 8-14-25-EB
A1: JCOS-CoNPS Plant Growth Study 2025
A2: write species name here: HEVI
A3: date: 8-14-25
A5: Plot # | B5: Number of expected plants 1. write this in from 7-10-25 tab | C5: Count individuals 1. write species code here. One individual per row. 2. stick with one species until it is complete. | D5: Plant height (cm) 1. pull tallest stem straight up 2. measure it's length | E5: Number of stems 1. count how many stems/individual *forbs only | F5: Code 1. Add B, H, or G if you see insect damage (B), herbivory (H), growth (G), flower (F)
A6: 1 | B6: 12 | C6: 1 | D6: 6 | E6: 1
C7: 2 | D7: 4 | E7: 1
C8: 3 | D8: 10.5 | E8: 1
C9: 4 | D9: 5.5 | E9: 1
C10: 5 | D10: 1.5 | E10: 1
C11: 6 | D11: 2.3 | E11: 1
C12: 7 | D12: 8 | E12: 2
C13: 8 | D13: 9.5 | E13: 1
C14: 9 | D14: 12 | E14: 1
C15: 10 | D15: 6 | E15: 1
C16: 11 | D16: 10.5 | E16: 1
C17: 12 | D17: 18 | E17: 1
A18: 2 | B18: 11 | C18: 1 | D18: 3.5 | E18: 1
C19: 2 | D19: 7 | E19: 1
C20: 3 | D20: 8 | E20: 1
C21: 4 | D21: 9 | E21: 1
C22: 5 | D22: 6 | E22: 1
C23: 6 | D23: 9 | E23: 1
C24: 7 | D24: 8.5 | E24: 1
A25: 7 | B25: 9 | C25: 1 | D25: 33 | E25: 1
C26: 2 | D26: 30.5 | E26: 2
C27: 3 | D27: 10.5 | E27: 1
C28: 4 | D28: 25.5 | E28: 1
C29: 5 | D29: 9 | E29: 1
C30: 6 | D30: 23 | E30: 1
C31: 7 | D31: 9 | E31: 1
C32: 8 | D32: 15.5 | E32: 3
C33: 9 | D33: 32.5 | E33: 1
A34: 8 | B34: 10 | C34: 1 | D34: 33.5 | E34: 1
C35: 2 | D35: 41.5 | E35: 1
C36: 3 | D36: 36 | E36: 1
C37: 4 | D37: 18 | E37: 1
C38: 5 | D38: 37 | E38: 1
C39: 6 | D39: 9.5 | E39: 1
C40: 7 | D40: 32.5 | E40: 1
C41: 8 | D41: 25 | E41: 1
...

Sheet 9-1-25-MG
A1: Survival rate | B1: ACMI | C1: ARLU | D1: HEVI | E1: SYER | F1: BOGR | G1: HECO | H1: NAVI | I1: PASM
A2: 1-F-S3 7-10 | B2: =39/50 -> 0.78 | C2: =13/15 -> 0.86666667 | D2: =12/12 -> 1 | E2: =4/15 -> 0.26666667 | F2: =4/7 -> 0.57142857 | G2: - | H2: =2/5 -> 0.4 | I2: =5/10 -> 0.5
A3: 2-NF-S3 7-10 | B3: =34/50 -> 0.68 | C3: =4/15 -> 0.26666667 | D3: =7/11 -> 0.63636364 | E3: =5/10 -> 0.5 | F3: =6/7 -> 0.85714286 | G3: - | H3: =0/5 -> 0 | I3: =1/10 -> 0.1
A4: Survival rate | B4: ACMI | C4: ARLU | D4: HEVI | E4: SYER | F4: BOGR | G4: HECO | H4: NAVI | I4: PASM
A5: 3-F-peat 7-10 | D5: =8/10 -> 0.8 | E5: =13/48 -> 0.27083333 | F5: =24/32 -> 0.75 | G5: =4/10 -> 0.4 | H5: =0/9 -> 0 | I5: -
A6: 4-NF-peat 7-10 | D6: =11/15 -> 0.73333333 | E6: =26/49 -> 0.53061224 | F6: =28/30 -> 0.93333333 | G6: - | H6: =0/9 -> 0 | I6: -
A7: Survival rate | B7: ACMI | C7: ARLU | D7: HEVI | E7: SYER | F7: BOGR | G7: HECO | H7: NAVI | I7: PASM
A8: 5-NF-MC 7-10BOGR+8-14 | E8: /9 | F8: =32/32 -> 1 | G8: =0/3 -> 0 | H8: =0/6 -> 0 | I8: -
A9: 6-F-peat 7-10BOGR+8-14 | B9: =9/40 -> 0.225 | E9: /23 | F9: =21/32 -> 0.65625 | G9: =4/5 -> 0.8 | H9: =0/4 -> 0 | I9: =4/9 -> 0.44444444
A10: 7-F-S3 8-14 | B10: =21/25 -> 0.84 | C10: =13/13 -> 1 | D10: =9/9 -> 1 | E10: =15/15 -> 1 | F10: =6/6 -> 1 | H10: =1/6 -> 0.16666667 | I10: =5/9 -> 0.55555556
A11: 8-NF-S3 8-14 | B11: =4/25 -> 0.16 | C11: =25/25 -> 1 | D11: =10/10 -> 1 | E11: =15/15 -> 1 | F11: =10/10 -> 1 | H11: =6/6 -> 1 | I11: =6/6 -> 1
A12: 9-F peat 9-11
A13: 10-NF peat 9-11
A14: 11-F MC 9-11
A15: 12NF MC 9-11
A20: 8-14-25 data added
A21: 9-1-25 data added

Sheet 9-1-25-LM
A1: JCOS-CoNPS Plant Growth Study 2025
A2: write species name here: HEVI
A3: date: 9/5/25
A5: Plot # | B5: Number of expected plants 1. write this in from 7-10-25 tab | C5: Count individuals 1. write species code here. One individual per row. 2. stick with one species until it is complete. | D5: Plant height (cm) 1. pull tallest stem straight up 2. measure it's length | E5: Number of stems 1. count how many stems/individual *forbs only | F5: Code 1. Add B, H, or G if you see insect damage (B), herbivory (H), or growth (G), flower (F)
A6: 1 | B6: 15 | C6: HEVI | D6: 18 | E6: 1 | F6: H
C7: HEVI | D7: 12 | E7: 1 | F7: F
C8: HEVI | D8: 4 | E8: 1 | F8: G, H
C9: HEVI | D9: 12 | E9: 1 | F9: G, H
C10: HEVI | D10: 21 | E10: 1 | F10: F
C11: HEVI | D11: 9 | E11: 1 | F11: G, H
C12: HEVI | D12: 6 | E12: 1
C13: HEVI | D13: 9 | E13: 1 | F13: G
C14: HEVI | D14: 17 | E14: 1 | F14: G
C15: HEVI | D15: 13 | E15: 1 | F15: G
C16: HEVI | D16: 4 | E16: 1 | F16: G
C17: HEVI | D17: 5 | E17: 1 | F17: G
B18: =count(D6:D18) -> 13 | C18: HEVI | D18: 8 | E18: 1 | F18: G
A19: 2 | B19: 15 | C19: HEVI | D19: 7 | E19: 1 | F19: G, H
C20: HEVI | D20: 5 | E20: 3 | F20: G, H
C21: HEVI | D21: 8 | E21: 1 | F21: G
B22: =count(D19:D22) -> 4 | C22: HEVI | D22: 6 | E22: 2 | F22: G
A23: 3 | B23: 21 | C23: HEVI | D23: 2 | E23: 2 | F23: G
C24: HEVI | D24: 2 | E24: 1 | F24: G
C25: HEVI | D25: 2 | E25: 1
C26: HEVI | D26: 5 | E26: 2 | F26: G
C27: HEVI | D27: 3 | E27: 1
C28: HEVI | D28: 6 | E28: 1 | F28: G
C29: HEVI | D29: 7 | E29: 1 | F29: G
C30: HEVI | D30: 2 | E30: 1
C31: HEVI | D31: 5 | E31: 1
C32: HEVI | D32: 4 | E32: 2
C33: HEVI | D33: 2 | E33: 1
C34: HEVI | D34: 2 | E34: 1
C35: HEVI | D35: 5 | E35: 1
C36: HEVI | D36: 4 | E36: 1
B37: =count(D23:D37) -> 15 | C37: HEVI | D37: 6 | E37: 1 | F37: G
A38: 4 | B38: 15 | C38: HEVI | D38: 3 | E38: 1 | F38: G
C39: HEVI | D39: 4 | E39: 1 | F39: G
C40: HEVI | D40: 4 | E40: 1 | F40: G
C41: HEVI | D41: 4 | E41: 1 | F41: G
...

Sheet 9-11-25-MG
A2: Survival rate | B2: ACMI | C2: ARLU | D2: HEVI | E2: SYER | F2: BOGR | G2: HECO | H2: NAVI | I2: PASM
A3: 1-F-S3 7-10 | B3: =39/50 -> 0.78 | C3: =13/15 -> 0.86666667 | D3: =12/12 -> 1 | E3: =4/15 -> 0.26666667 | F3: =4/7 -> 0.57142857 | G3: - | H3: =2/5 -> 0.4 | I3: =5/10 -> 0.5
A4: 2-NF-S3 7-10 | B4: =34/50 -> 0.68 | C4: =4/15 -> 0.26666667 | D4: =7/11 -> 0.63636364 | E4: =5/10 -> 0.5 | F4: =6/7 -> 0.85714286 | G4: - | H4: =0/5 -> 0 | I4: =1/10 -> 0.1
A5: Survival rate | B5: ACMI | C5: ARLU | D5: HEVI | E5: SYER | F5: BOGR | G5: HECO | H5: NAVI | I5: PASM
A6: 3-F-peat 7-10 | D6: =8/10 -> 0.8 | E6: =13/48 -> 0.27083333 | F6: =24/32 -> 0.75 | G6: =4/10 -> 0.4 | H6: =0/9 -> 0 | I6: -
A7: 4-NF-peat 7-10 | D7: =11/15 -> 0.73333333 | E7: =26/49 -> 0.53061224 | F7: =28/30 -> 0.93333333 | G7: - | H7: =0/9 -> 0 | I7: -
A8: Survival rate | B8: ACMI | C8: ARLU | D8: HEVI | E8: SYER | F8: BOGR | G8: HECO | H8: NAVI | I8: PASM
A9: 5-NF-MC 7-10BOGR+8-14 | E9: /9 | F9: =32/32 -> 1 | G9: =0/3 -> 0 | H9: =0/6 -> 0 | I9: -
A10: 6-F-peat 7-10BOGR+8-14 | B10: =9/40 -> 0.225 | E10: /23 | F10: =21/32 -> 0.65625 | G10: =4/5 -> 0.8 | H10: =0/4 -> 0 | I10: =4/9 -> 0.44444444
A11: 7-F-S3 8-14 | B11: =21/25 -> 0.84 | C11: =13/13 -> 1 | D11: =9/9 -> 1 | E11: =15/15 -> 1 | F11: =6/6 -> 1 | G11: - | H11: =1/6 -> 0.16666667 | I11: =5/9 -> 0.55555556
A12: 8-NF-S3 8-14 | B12: =4/25 -> 0.16 | C12: =25/25 -> 1 | D12: =10/10 -> 1 | E12: =15/15 -> 1 | F12: =10/10 -> 1 | G12: - | H12: =6/6 -> 1 | I12: =6/6 -> 1
A13: 9-F peat 9-11 | B13: 22 | C13: 24 | D13: 5 | F13: 25
A14: 10-NF peat 9-11 | B14: 24 | C14: 24 | F14: 24 | H14: 3 | I14: 9
A15: 11-F MC 9-11 | B15: 20 | C15: 23 | D15: 7 | F15: 25
A16: 12NF MC 9-11 | B16: 24 | C16: 24 | F16: 24
A21: 8-14-25 data added
A22: 9-1-25 data added
A23: 9-11-25 data added

Sheet 9-11-25-KT
A1: JCOS-CoNPS Plant Growth Study 2025
A2: write species name here: BOGR
A3: date: 9/11/2025
A5: Plot # | B5: Number of expected plants 1. write this in from 7-10-25 tab | C5: Count individuals 1. write species code here. One individual per row. 2. stick with one species until it is complete. | D5: Plant height (cm) 1. pull tallest stem straight up 2. measure it's length | E5: Number of stems 1. count how many stems/individual *forbs only | F5: Code 1. Add B, H, or G if you see insect damage (B), herbivory (H), growth (G), flower (F)
A6: 1 | C6: 1 | D6: 15
A7: 1 | C7: 2 | D7: 10
A8: 1 | C8: 3 | D8: 15
A9: 1 | C9: 4 | D9: 10
A10: 2 | C10: 1 | D10: 10
A11: 2 | C11: 2 | D11: 23
A12: 2 | C12: 3 | D12: 13
A13: 2 | C13: 4 | D13: 11
A14: 3 | C14: 1 | D14: 4
A15: 3 | C15: 2 | D15: 5
A16: 3 | C16: 3 | D16: 2
A17: 3 | C17: 4 | D17: 7
... A49: 4 | C49: 10 | D49: 5
A50: 9 | B50: 25 | C50: 1 | D50: 11
A51: 9 | B51: 25 | C51: 2 | D51: 10
A52: 9 | B52: 25 | C52: 3 | D52: 8
A53: 9 | B53: 25 | C53: 4 | D53: 8
A54: 9 | B54: 25 | C54: 5 | D54: 9
A55: 9 | B55: 25 | C55: 6 | D55: 9
A56: 9 | B56: 25 | C56: 7 | D56: 11
A57: 9 | B57: 25 | C57: 8 | D57: 10
A58: 9 | B58: 25 | C58: 9 | D58: 13
A59: 9 | B59: 25 | C59: 10 | D59: 5
A60: 9 | B60: 25 | C60: 11 | D60: 12
A61: 9 | B61: 25 | C61: 12 | D61: 11
... A70: 9 | B70: 25 | C70: 21 | D70: 10
A71: 9 | B71: 25 | C71: 22 | D71: 11 | G71: =average(D50:D71) -> 9.7727273
A72: 10 | B72: 24 | C72: 1 | D72: 8
A73: 10 | B73: 24 | C73: 2 | D73: 11
A74: 10 | B74: 24 | C74: 3 | D74: 9
A75: 10 | B75: 24 | C75: 4 | D75: 11
A76: 10 | B76: 24 | C76: 5 | D76: 10
A77: 10 | B77: 24 | C77: 6 | D77: 7
A78: 10 | B78: 24 | C78: 7 | D78: 7
A79: 10 | B79: 24 | C79: 8 | D79: 9
A80: 10 | B80: 24 | C80: 9 | D80: 5
...

Sheet 10-9-25-EB
A1: JCOS-CoNPS Plant Growth Study 2025
A2: write species name here: HEVI
A3: date: 10.9.25
A5: Plot # | B5: Number of expected plants 1. write this in from 7-10-25 tab | C5: Count individuals 1. write species code here. One individual per row. 2. stick with one species until it is complete. | D5: Plant height (cm) 1. pull tallest stem straight up 2. measure it's length | E5: Number of stems 1. count how many stems/individual *forbs only | F5: Code 1. Add B, H, or G if you see insect damage (B), herbivory (H), or growth (G), flower (F)
A6: 1 | B6: 15 | C6: 1 | D6: 17 | E6: 1 | F6: G,F,B
C7: 2 | D7: 3.5 | E7: 1 | F7: G
C8: 3 | D8: 21 | E8: 1 | F8: G,F
C9: 4 | D9: 14 | E9: 1 | F9: G,F
C10: 5 | D10: 21 | E10: 1 | F10: G,F
C11: 6 | D11: 5 | E11: 1 | F11: G
C12: 7 | D12: 11 | E12: 1 | F12: G,F
C13: 8 | D13: 12 | E13: 1 | F13: G
C14: 9 | D14: 18.5 | E14: 1 | F14: G
C15: 10 | D15: 9.5 | E15: 1 | F15: G
C16: 11 | D16: 5.5 | E16: 1 | F16: G
C17: 12 | D17: 5.5 | E17: 1 | F17: G
C18: 13 | D18: 1 | E18: 1 | F18: G | G18: =average(D6:D18) -> 11.115385 | H18: =average(E6:E18) -> 1
A19: 2 | B19: 15 | C19: 1 | D19: 9 | E19: 1 | F19: G,B
C20: 2 | D20: 4.5 | E20: 1 | F20: G,B
C21: 3 | D21: 8 | E21: 1 | F21: G,B
C22: 4 | D22: 6 | E22: 1 | F22: G,B
C23: 5
C24: 6 | D24: 3 | E24: 1 | F24: G,B
C25: 7
C26: 8
C27: 9 | G27: =average(D19:D27) -> 6.1 | H27: =average(E19:E27) -> 1
A28: 3 | B28: 21 | C28: 1 | D28: 5.5 | E28: 1 | F28: G
C29: 2 | D29: 2.5 | E29: 1 | F29: G
C30: 3 | D30: 3 | E30: 1 | F30: G
C31: 4 | D31: 3.5 | E31: 1 | F31: G
C32: 5 | D32: 4 | E32: 1 | F32: G,B
C33: 6 | D33: 3 | E33: 1 | F33: G
C34: 7 | D34: 2 | E34: 1 | F34: G
C35: 8 | D35: 3 | E35: 1 | F35: G | G35: =average(D28:D35) -> 3.3125 | H35: =average(E28:E35) -> 1
A36: 4 | B36: 15 | C36: 1 | D36: 4 | E36: 1 | F36: G
C37: 2 | D37: 3.5 | E37: 1 | F37: G,B
C38: 3 | D38: 4.5 | E38: 1 | F38: G,B
C39: 4 | D39: 3.5 | E39: 1 | F39: G
C40: 5 | D40: 4 | E40: 1 | F40: G
C41: 6 | D41: 3.5 | E41: 1 | F41: G
...

Sheet 10-23-25 AB
A1: JCOS-CoNPS Plant Growth Study 2025
A2: write species name here: ACMI
A3: date: 10-23-25
A5: Plot # | B5: Number of expected plants 1. write this in from 7-10-25 tab | C5: Count individuals 1. write species code here. One individual per row. 2. stick with one species until it is complete. | D5: Plant height (cm) 1. pull tallest stem straight up 2. measure it's length | E5: Number of stems 1. count how many stems/individual *forbs only | F5: Code 1. Add B, H, or G if you see insect damage (B), herbivory (H), growth (G), flower (F) | G5: count | H5: average height | I5: average # of stems
A6: 1 | C6: ACMI | D6: 9 | E6: 1 | J6: *No ACMI in plots 3, 4, 5
D7: 8 | E7: 1
D8: 7 | E8: 2
D9: 6 | E9: 2
D10: 14 | E10: 1
D11: 9 | E11: 1
D12: 13 | E12: 2
D13: 10 | E13: 2
D14: 8 | E14: 2
D15: 8 | E15: 2
D16: 5 | E16: 3
D17: 6 | E17: 1
D18: 8 | E18: 2
... D37: 11 | E37: 1
D38: 9 | E38: 1 | G38: =count(D6:D38) -> 33 | H38: =average(D6:D38) -> 8.4242424 | I38: =average(E6:E38) -> 1.6060606
A39: 2 | C39: ACMI | D39: 7 | E39: 2
D40: 4 | E40: 1
D41: 10 | E41: 1
D42: 11 | E42: 2
D43: 8 | E43: 3
D44: 11 | E44: 2
D45: 7 | E45: 3
D46: 7 | E46: 2
D47: 8 | E47: 2
D48: 12 | E48: 3
D49: 9 | E49: 3
D50: 10 | E50: 2
D51: 13 | E51: 2
... D74: 7 | E74: 2
D75: 6 | E75: 1 | G75: =count(D39:D75) -> 37 | H75: =average(D39:D75) -> 8.6756757 | I75: =average(E39:E75) -> 2.1891892
A76: 6 | C76: ACMI | D76: 3 | E76: 1
D77: 7 | E77: 1
D78: 5 | E78: 1
D79: 7 | E79: 1
D80: 4 | E80: 1
D81: 5 | E81: 1
...
